Workbook

Sheet Setup
B1: Revision date | C1: Revision
B2: =MAX(B5:B1000) -> 46161 | C2: =VLOOKUP(B2,B5:C1000,2) -> PA3
B4: Revision history
B5: 46129 | C5: PA1 | D5: Initial version.
B6: 46150 | C6: PA2 | D6: Updated d2a_DIST_B0_St2_0_PTAT and d2a_DIST_B0_St2_1_PTAT description with correct related channels
B7: 46161 | C7: PA3 | D7: Added ADC sheet and some missing bias regs

Sheet SYS
A1: Address Offset | C1: Revision date | D1: Revision | E1: ED
A2: N/A | C2: =Setup!B2 -> 46161 | D2: =Setup!C2 -> PA3 | E2: Stampede
A3: Address | B3: Address hex | C3: Reg Name | D3: Field Name | E3: Description | F3: Msb | G3: Lsb | H3: Bit Length | I3: Type | J3: Default | K3: Signal Name | L3: Dir
A5: 4096 | B5: =_xlfn.CONCAT("0x",DEC2HEX(A5,4)) -> 0x1000 | C5: chip_info | D5: chip_id | E5: Current CHIP setting either from external pins, enumeration, or written by unique ID | F5: 7 | G5: 0 | H5: 8 | I5: R
A6: 4096 | B6: =_xlfn.CONCAT("0x",DEC2HEX(A6,4)) -> 0x1000 | C6: chip_info | D6: version_id | E6: Version identifier | F6: 15 | G6: 8 | H6: 8 | I6: R | J6: 220
A7: 4097 | B7: =_xlfn.CONCAT("0x",DEC2HEX(A7,4)) -> 0x1001 | C7: unique_id_l | D7: uid_low | E7: 32-bit Unique ID for each chip bits [15:0] | F7: 15 | G7: 0 | H7: 16 | I7: R
A8: 4098 | B8: =_xlfn.CONCAT("0x",DEC2HEX(A8,4)) -> 0x1002 | C8: unique_id_h | D8: uid_high | E8: 32-bit Unique ID for each chip bits [16:31] | F8: 15 | G8: 0 | H8: 16 | I8: R
A9: 4099 | B9: =_xlfn.CONCAT("0x",DEC2HEX(A9,4)) -> 0x1003 | C9: status | D9: soft_reset | E9: soft_reset in progress [0] | F9: 0 | G9: 0 | H9: 1 | I9: R
A10: 4099 | B10: =_xlfn.CONCAT("0x",DEC2HEX(A10,4)) -> 0x1003 | C10: status | D10: reserved | E10: reserved_bits[4:1] | F10: 4 | G10: 1 | H10: 4 | I10: R
A11: 4100 | B11: =_xlfn.CONCAT("0x",DEC2HEX(A11,4)) -> 0x1004 | C11: output_daisy_amp_control | D11: reserved | E11: reserved_bits[11:0] | F11: 11 | G11: 0 | H11: 12 | I11: R
A12: 4100 | B12: =_xlfn.CONCAT("0x",DEC2HEX(A12,4)) -> 0x1004 | C12: output_daisy_amp_control | D12: beam_pd_supply_pwrdn_sw | E12: Bits[13:12] = Beam[1:0] PD Supply power-down switches | F12: 13 | G12: 12 | H12: 2 | I12: RW
A13: 4100 | B13: =_xlfn.CONCAT("0x",DEC2HEX(A13,4)) -> 0x1004 | C13: output_daisy_amp_control | D13: reserved | E13: reserved_bits[15:14] | F13: 15 | G13: 14 | H13: 2 | I13: R
A14: 4101 | B14: =_xlfn.CONCAT("0x",DEC2HEX(A14,4)) -> 0x1005 | C14: common_gain_b0 | D14: b0_common_gain | E14: Common gain setting for beam0 applied after combining | F14: 5 | G14: 0 | H14: 6 | I14: RW
A15: 4101 | B15: =_xlfn.CONCAT("0x",DEC2HEX(A15,4)) -> 0x1005 | C15: common_gain_b0 | D15: pulse_en_1 | E15: latch enabled with Pulse_en_1 | F15: 6 | G15: 6 | H15: 1 | I15: RW
A16: 4102 | B16: =_xlfn.CONCAT("0x",DEC2HEX(A16,4)) -> 0x1006 | C16: common_gain_b1 | D16: b1_common_gain | E16: Common gain setting for beam1 applied after combining | F16: 5 | G16: 0 | H16: 6 | I16: RW

Sheet CTRL
A1: Address Offset | C1: Revision date | D1: Revision | E1: ED
A2: N/A | C2: =Setup!B2 -> 46161 | D2: =Setup!C2 -> PA3 | E2: Stampede
A3: Address | B3: Address hex | C3: Reg Name | D3: Field Name | E3: Description | F3: Msb | G3: Lsb | H3: Bit Length | I3: Type | J3: Default | K3: Signal Name | L3: Dir
A5: 4104 | B5: =_xlfn.CONCAT("0x",DEC2HEX(A5,4)) -> 0x1008 | C5: center_control | D5: centerbias_en | E5: Enable for the center bias generator | F5: 0 | G5: 0 | H5: 1 | I5: RW
A6: 4104 | B6: =_xlfn.CONCAT("0x",DEC2HEX(A6,4)) -> 0x1008 | C6: center_control | D6: centermirror_en | F6: 1 | G6: 1 | H6: 1 | I6: RW
A7: 4104 | B7: =_xlfn.CONCAT("0x",DEC2HEX(A7,4)) -> 0x1008 | C7: center_control | D7: center_pd_override | E7: Override global power down for center | F7: 2 | G7: 2 | H7: 1 | I7: RW
A8: 4104 | B8: =_xlfn.CONCAT("0x",DEC2HEX(A8,4)) -> 0x1008 | C8: center_control | D8: spi_daisy_chain_disable | E8: Disable SPI daisy chain outputs | F8: 3 | G8: 3 | H8: 1 | I8: RW
A9: 4104 | B9: =_xlfn.CONCAT("0x",DEC2HEX(A9,4)) -> 0x1008 | C9: center_control | D9: global_power_down | E9: Global power down for center and Quads | F9: 4 | G9: 4 | H9: 1 | I9: RW
A10: 4104 | B10: =_xlfn.CONCAT("0x",DEC2HEX(A10,4)) -> 0x1008 | C10: center_control | D10: pulse_en_2 | E10: latch enabled with pulse_en_2 | F10: 7 | G10: 7 | H10: 1 | I10: RW
A11: 4104 | B11: =_xlfn.CONCAT("0x",DEC2HEX(A11,4)) -> 0x1008 | C11: center_control | D11: ds_sel | E11: drive strength selection Ds_dout[9:8] Ds_chain[11:10] | F11: 11 | G11: 8 | H11: 4 | I11: RW
A12: 4104 | B12: =_xlfn.CONCAT("0x",DEC2HEX(A12,4)) -> 0x1008 | C12: center_control | D12: center_efuse_pwrdn_dis | E12: EFUSE power down disable | F12: 12 | G12: 12 | H12: 1 | I12: RW
A13: 4105 | B13: =_xlfn.CONCAT("0x",DEC2HEX(A13,4)) -> 0x1009 | C13: center_dist_b0 | D13: dist_b0_st1_en | E13: Distribution network at Beam 0. 1 for enable and 0 for disable: CH0 [0] CH1 [1] CH2 [2] CH3 [3] | F13: 3 | G13: 0 | H13: 4 | I13: RW
A14: 4105 | B14: =_xlfn.CONCAT("0x",DEC2HEX(A14,4)) -> 0x1009 | C14: center_dist_b0 | D14: reserved | E14: reserved_bits[7:4] | F14: 7 | G14: 4 | H14: 4 | I14: N
A15: 4105 | B15: =_xlfn.CONCAT("0x",DEC2HEX(A15,4)) -> 0x1009 | C15: center_dist_b0 | D15: center_bias_beam0_en | E15: Bias generation bit | F15: 8 | G15: 8 | H15: 1 | I15: RW
A16: 4105 | B16: =_xlfn.CONCAT("0x",DEC2HEX(A16,4)) -> 0x1009 | C16: center_dist_b0 | D16: beam0_pwrdn | E16: Power_down controls for override mode | F16: 13 | G16: 9 | H16: 5 | I16: RW
A17: 4105 | B17: =_xlfn.CONCAT("0x",DEC2HEX(A17,4)) -> 0x1009 | C17: center_dist_b0 | D17: reserved | E17: reserved_bits[14] | F17: 14 | G17: 14 | H17: 1 | I17: RW
A18: 4106 | B18: =_xlfn.CONCAT("0x",DEC2HEX(A18,4)) -> 0x100A | C18: center_dist_b1 | D18: dist_b1_st1_en | E18: Distribution network at Beam 1. 1 for enable and 0 for disable: CH0 [0] CH1 [1] CH2 [2] CH3 [3] | F18: 3 | G18: 0 | H18: 4 | I18: RW
... A33: 4112 | B33: =_xlfn.CONCAT("0x",DEC2HEX(A33,4)) -> 0x1010 | C33: quad0_pwrdn | D33: ch0_h_pwrdn | E33: 0 for power off and 1 for power on at CH0 H: PA [0] Pre-Driver [1] Combiner [2] | F33: 5 | G33: 3 | H33: 3 | I33: RW
A34: 4112 | B34: =_xlfn.CONCAT("0x",DEC2HEX(A34,4)) -> 0x1010 | C34: quad0_pwrdn | D34: ch0_pwrdn_override | F34: 6 | G34: 6 | H34: 1 | I34: RW
A35: 4112 | B35: =_xlfn.CONCAT("0x",DEC2HEX(A35,4)) -> 0x1010 | C35: quad0_pwrdn | D35: ch0_bias_en | F35: 7 | G35: 7 | H35: 1 | I35: RW
A36: 4112 | B36: =_xlfn.CONCAT("0x",DEC2HEX(A36,4)) -> 0x1010 | C36: quad0_pwrdn | D36: pulse_en_ch0_2 | F36: 8 | G36: 8 | H36: 1 | I36: RW
A37: 4112 | B37: =_xlfn.CONCAT("0x",DEC2HEX(A37,4)) -> 0x1010 | C37: quad0_pwrdn | D37: ch0_efuse_pwrdn_dis | E37: disables the auto power gating of effuse (not latched) | F37: 9 | G37: 9 | H37: 1 | I37: RW
A38: 4113 | B38: =_xlfn.CONCAT("0x",DEC2HEX(A38,4)) -> 0x1011 | C38: quad1_pwrdn | D38: ch1_v_pwrdn | E38: 0 for power off and 1 for power on at CH1 V: PA [0] Pre-Driver [1] Combiner [2] | F38: 2 | G38: 0 | H38: 3 | I38: RW
A39: 4113 | B39: =_xlfn.CONCAT("0x",DEC2HEX(A39,4)) -> 0x1011 | C39: quad1_pwrdn | D39: ch1_h_pwrdn | E39: 0 for power off and 1 for power on at CH1 H: PA [0] Pre-Driver [1] Combiner [2] | F39: 5 | G39: 3 | H39: 3 | I39: RW
A40: 4113 | B40: =_xlfn.CONCAT("0x",DEC2HEX(A40,4)) -> 0x1011 | C40: quad1_pwrdn | D40: ch1_pwrdn_override | F40: 6 | G40: 6 | H40: 1 | I40: RW
A41: 4113 | B41: =_xlfn.CONCAT("0x",DEC2HEX(A41,4)) -> 0x1011 | C41: quad1_pwrdn | D41: ch1_bias_en | F41: 7 | G41: 7 | H41: 1 | I41: RW
A42: 4113 | B42: =_xlfn.CONCAT("0x",DEC2HEX(A42,4)) -> 0x1011 | C42: quad1_pwrdn | D42: pulse_en_ch1_2 | F42: 8 | G42: 8 | H42: 1 | I42: RW
A43: 4113 | B43: =_xlfn.CONCAT("0x",DEC2HEX(A43,4)) -> 0x1011 | C43: quad1_pwrdn | D43: ch1_efuse_pwrdn_dis | E43: disables the auto power gating of efuse (not latched) | F43: 9 | G43: 9 | H43: 1 | I43: RW
A44: 4114 | B44: =_xlfn.CONCAT("0x",DEC2HEX(A44,4)) -> 0x1012 | C44: quad2_pwrdn | D44: ch2_v_pwrdn | E44: 0 for power off and 1 for power on at CH2 V: PA [0] Pre-Driver [1] Combiner [2] | F44: 2 | G44: 0 | H44: 3 | I44: RW
A45: 4114 | B45: =_xlfn.CONCAT("0x",DEC2HEX(A45,4)) -> 0x1012 | C45: quad2_pwrdn | D45: ch2_h_pwrdn | E45: 0 for power off and 1 for power on at CH2 H: PA [0] Pre-Driver [1] Combiner [2] | F45: 5 | G45: 3 | H45: 3 | I45: RW
A46: 4114 | B46: =_xlfn.CONCAT("0x",DEC2HEX(A46,4)) -> 0x1012 | C46: quad2_pwrdn | D46: ch2_pwrdn_override | F46: 6 | G46: 6 | H46: 1 | I46: RW
A47: 4114 | B47: =_xlfn.CONCAT("0x",DEC2HEX(A47,4)) -> 0x1012 | C47: quad2_pwrdn | D47: ch2_bias_en | F47: 7 | G47: 7 | H47: 1 | I47: RW
A48: 4114 | B48: =_xlfn.CONCAT("0x",DEC2HEX(A48,4)) -> 0x1012 | C48: quad2_pwrdn | D48: pulse_en_ch2_2 | F48: 8 | G48: 8 | H48: 1 | I48: RW
A49: 4114 | B49: =_xlfn.CONCAT("0x",DEC2HEX(A49,4)) -> 0x1012 | C49: quad2_pwrdn | D49: ch2_efuse_pwrdn_dis | E49: disables the auto power gating of effuse (not latched) | F49: 9 | G49: 9 | H49: 1 | I49: RW
A50: 4115 | B50: =_xlfn.CONCAT("0x",DEC2HEX(A50,4)) -> 0x1013 | C50: quad3_pwrdn | D50: ch3_v_pwrdn | E50: 0 for power off and 1 for power on at CH3 V: PA [0] Pre-Driver [1] Combiner [2] | F50: 2 | G50: 0 | H50: 3 | I50: RW
A51: 4115 | B51: =_xlfn.CONCAT("0x",DEC2HEX(A51,4)) -> 0x1013 | C51: quad3_pwrdn | D51: ch3_h_pwrdn | E51: 0 for power off and 1 for power on at CH3 H: PA [0] Pre-Driver [1] Combiner [2] | F51: 5 | G51: 3 | H51: 3 | I51: RW
A52: 4115 | B52: =_xlfn.CONCAT("0x",DEC2HEX(A52,4)) -> 0x1013 | C52: quad3_pwrdn | D52: ch3_pwrdn_override | F52: 6 | G52: 6 | H52: 1 | I52: RW
A53: 4115 | B53: =_xlfn.CONCAT("0x",DEC2HEX(A53,4)) -> 0x1013 | C53: quad3_pwrdn | D53: ch3_bias_en | F53: 7 | G53: 7 | H53: 1 | I53: RW
A54: 4115 | B54: =_xlfn.CONCAT("0x",DEC2HEX(A54,4)) -> 0x1013 | C54: quad3_pwrdn | D54: pulse_en_ch3_2 | F54: 8 | G54: 8 | H54: 1 | I54: RW
A55: 4115 | B55: =_xlfn.CONCAT("0x",DEC2HEX(A55,4)) -> 0x1013 | C55: quad3_pwrdn | D55: ch3_efuse_pwrdn_dis | E55: disables the auto power gating of effuse (not latched) | F55: 9 | G55: 9 | H55: 1 | I55: RW
...

Sheet CAL
A1: Address Offset | C1: Revision date | D1: Revision | E1: ED
A2: N/A | C2: =Setup!B2 -> 46161 | D2: =Setup!C2 -> PA3 | E2: Stampede
A3: Address | B3: Address hex | C3: Reg Name | D3: Field Name | E3: Description | F3: Msb | G3: Lsb | H3: Bit Length | I3: Type | J3: Default | K3: Signal Name | L3: Dir
A5: 4116 | B5: =_xlfn.CONCAT("0x",DEC2HEX(A5,4)) -> 0x1014 | C5: cal_freq_adj_ch0 | D5: ch0_cal_freq_sel_beam0 | E5: Frequency selection for calibration optimization Beam0 | F5: 2 | G5: 0 | H5: 3 | I5: RW
A6: 4116 | B6: =_xlfn.CONCAT("0x",DEC2HEX(A6,4)) -> 0x1014 | C6: cal_freq_adj_ch0 | D6: ch0_cal_freq_sel_beam1 | E6: Frequency selection for calibration optimization Beam1 | F6: 5 | G6: 3 | H6: 3 | I6: RW
A7: 4116 | B7: =_xlfn.CONCAT("0x",DEC2HEX(A7,4)) -> 0x1014 | C7: cal_freq_adj_ch0 | D7: pulse_en_ch0_3 | F7: 9 | G7: 9 | H7: 1 | I7: RW
A8: 4117 | B8: =_xlfn.CONCAT("0x",DEC2HEX(A8,4)) -> 0x1015 | C8: cal_freq_adj_ch1 | D8: ch1_cal_freq_sel_beam0 | E8: Frequency selection for calibration optimization Beam0 | F8: 2 | G8: 0 | H8: 3 | I8: RW
A9: 4117 | B9: =_xlfn.CONCAT("0x",DEC2HEX(A9,4)) -> 0x1015 | C9: cal_freq_adj_ch1 | D9: ch1_cal_freq_sel_beam1 | E9: Frequency selection for calibration optimization Beam1 | F9: 5 | G9: 3 | H9: 3 | I9: RW
A10: 4117 | B10: =_xlfn.CONCAT("0x",DEC2HEX(A10,4)) -> 0x1015 | C10: cal_freq_adj_ch1 | D10: pulse_en_ch1_3 | F10: 9 | G10: 9 | H10: 1 | I10: RW
A11: 4118 | B11: =_xlfn.CONCAT("0x",DEC2HEX(A11,4)) -> 0x1016 | C11: cal_freq_adj_ch2 | D11: ch2_cal_freq_sel_beam0 | E11: Frequency selection for calibration optimization Beam0 | F11: 2 | G11: 0 | H11: 3 | I11: RW
A12: 4118 | B12: =_xlfn.CONCAT("0x",DEC2HEX(A12,4)) -> 0x1016 | C12: cal_freq_adj_ch2 | D12: ch2_cal_freq_sel_beam1 | E12: Frequency selection for calibration optimization Beam1 | F12: 5 | G12: 3 | H12: 3 | I12: RW
A13: 4118 | B13: =_xlfn.CONCAT("0x",DEC2HEX(A13,4)) -> 0x1016 | C13: cal_freq_adj_ch2 | D13: pulse_en_ch2_3 | F13: 9 | G13: 9 | H13: 1 | I13: RW
A14: 4119 | B14: =_xlfn.CONCAT("0x",DEC2HEX(A14,4)) -> 0x1017 | C14: cal_freq_adj_ch3 | D14: ch3_cal_freq_sel_beam0 | E14: Frequency selection for calibration optimization Beam0 | F14: 2 | G14: 0 | H14: 3 | I14: RW
A15: 4119 | B15: =_xlfn.CONCAT("0x",DEC2HEX(A15,4)) -> 0x1017 | C15: cal_freq_adj_ch3 | D15: ch3_cal_freq_sel_beam1 | E15: Frequency selection for calibration optimization Beam1 | F15: 5 | G15: 3 | H15: 3 | I15: RW
A16: 4119 | B16: =_xlfn.CONCAT("0x",DEC2HEX(A16,4)) -> 0x1017 | C16: cal_freq_adj_ch3 | D16: pulse_en_ch3_3 | F16: 9 | G16: 9 | H16: 1 | I16: RW
A17: 4168 | B17: =_xlfn.CONCAT("0x",DEC2HEX(A17,4)) -> 0x1048 | C17: ch0_comb_cbias | D17: ch0_h_comb_cbias | E17: Middle cascode device gate voltage of 3-to-1 combiner for CH0 H [2:0] | F17: 2 | G17: 0 | H17: 3 | I17: RW
A18: 4168 | B18: =_xlfn.CONCAT("0x",DEC2HEX(A18,4)) -> 0x1048 | C18: ch0_comb_cbias | D18: ch0_v_comb_cbias | E18: Middle cascode device gate voltage of 3-to-1 combiner for CH0 V [2:0] | F18: 10 | G18: 8 | H18: 3 | I18: RW
A19: 4169 | B19: =_xlfn.CONCAT("0x",DEC2HEX(A19,4)) -> 0x1049 | C19: ch1_comb_cbias | D19: ch1_h_comb_cbias | E19: Middle cascode device gate voltage of 3-to-1 combiner for CH1 H [2:0] | F19: 2 | G19: 0 | H19: 3 | I19: RW
A20: 4169 | B20: =_xlfn.CONCAT("0x",DEC2HEX(A20,4)) -> 0x1049 | C20: ch1_comb_cbias | D20: ch1_v_comb_cbias | E20: Middle cascode device gate voltage of 3-to-1 combiner for CH1 V [2:0] | F20: 10 | G20: 8 | H20: 3 | I20: RW
A21: 4170 | B21: =_xlfn.CONCAT("0x",DEC2HEX(A21,4)) -> 0x104A | C21: ch2_comb_cbias | D21: ch2_h_comb_cbias | E21: Middle cascode device gate voltage of 3-to-1 combiner for CH2 H [2:0] | F21: 2 | G21: 0 | H21: 3 | I21: RW
A22: 4170 | B22: =_xlfn.CONCAT("0x",DEC2HEX(A22,4)) -> 0x104A | C22: ch2_comb_cbias | D22: ch2_v_comb_cbias | E22: Middle cascode device gate voltage of 3-to-1 combiner for CH2 V [2:0] | F22: 10 | G22: 8 | H22: 3 | I22: RW
A23: 4171 | B23: =_xlfn.CONCAT("0x",DEC2HEX(A23,4)) -> 0x104B | C23: ch3_comb_cbias | D23: ch3_h_comb_cbias | E23: Middle cascode device gate voltage of 3-to-1 combiner for CH3 H [2:0] | F23: 2 | G23: 0 | H23: 3 | I23: RW
A24: 4171 | B24: =_xlfn.CONCAT("0x",DEC2HEX(A24,4)) -> 0x104B | C24: ch3_comb_cbias | D24: ch3_v_comb_cbias | E24: Middle cascode device gate voltage of 3-to-1 combiner for CH3 V [2:0] | F24: 10 | G24: 8 | H24: 3 | I24: RW
A25: 4188 | B25: =_xlfn.CONCAT("0x",DEC2HEX(A25,4)) -> 0x105C | C25: ch0_h_attn_cal | D25: ch0_h_b0_attn_cal | E25: RTPS amplitude cal attenuation for CH0 H at Beam0; 4-dB range, 0.25-dB/step [3:0] | F25: 3 | G25: 0 | H25: 4 | I25: RW
A26: 4188 | B26: =_xlfn.CONCAT("0x",DEC2HEX(A26,4)) -> 0x105C | C26: ch0_h_attn_cal | D26: ch0_h_b1_attn_cal | E26: RTPS amplitude cal attenuation for CH0 H at Beam1; 4-dB range, 0.25-dB/step [11:8] | F26: 11 | G26: 8 | H26: 4 | I26: RW
A27: 4189 | B27: =_xlfn.CONCAT("0x",DEC2HEX(A27,4)) -> 0x105D | C27: ch1_h_attn_cal | D27: ch1_h_b0_attn_cal | E27: RTPS amplitude cal attenuation for CH1 H at Beam0; 4-dB range, 0.25-dB/step [3:0] | F27: 3 | G27: 0 | H27: 4 | I27: RW
A28: 4189 | B28: =_xlfn.CONCAT("0x",DEC2HEX(A28,4)) -> 0x105D | C28: ch1_h_attn_cal | D28: ch1_h_b1_attn_cal | E28: RTPS amplitude cal attenuation for CH1 H at Beam1; 4-dB range, 0.25-dB/step [11:8] | F28: 11 | G28: 8 | H28: 4 | I28: RW
... A56: 4203 | B56: =_xlfn.CONCAT("0x",DEC2HEX(A56,4)) -> 0x106B | C56: ch3_captune | D56: ch3_v_comb_out_captune | E56: Capacitance tune for CH3 V combiner output [12:11] | F56: 12 | G56: 11 | H56: 2 | I56: RW

Sheet BIAS
A1: Address Offset | C1: Revision date | D1: Revision | E1: ED
A2: N/A | C2: =Setup!B2 -> 46161 | D2: =Setup!C2 -> PA3 | E2: Stampede
A3: Address | B3: Address hex | C3: Reg Name | D3: Field Name | E3: Description | F3: Msb | G3: Lsb | H3: Bit Length | I3: Type | J3: Default | K3: Signal Name | L3: Dir
A5: 4152 | B5: =_xlfn.CONCAT("0x",DEC2HEX(A5,4)) -> 0x1038 | C5: ="bias_ctrl" & "_" & (A5-4152) -> bias_ctrl_0 | D5: d2a_CH0_H_PTAT_St1 | E5: PTAT current bias of PA for CH0 H | F5: 5 | G5: 0 | H5: 6 | I5: RW
A6: 4152 | B6: =_xlfn.CONCAT("0x",DEC2HEX(A6,4)) -> 0x1038 | C6: ="bias_ctrl" & "_" & (A6-4152) -> bias_ctrl_0 | D6: d2a_CH0_H_PTAT_St2 | E6: PTAT current bias of PA Driver for CH0 H | F6: 13 | G6: 8 | H6: 6 | I6: RW
A7: 4156 | B7: =_xlfn.CONCAT("0x",DEC2HEX(A7,4)) -> 0x103C | C7: ="bias_ctrl" & "_" & (A7-4152) -> bias_ctrl_4 | D7: d2a_CH0_H_PTAT_St3 | E7: PTAT current bias of combiner for CH0 H | F7: 5 | G7: 0 | H7: 6 | I7: RW
A8: 4156 | B8: =_xlfn.CONCAT("0x",DEC2HEX(A8,4)) -> 0x103C | C8: ="bias_ctrl" & "_" & (A8-4152) -> bias_ctrl_4 | D8: d2a_CH0_H_CTAT | E8: <3:1> to efuse; CTAT current for 3to1 Comb with 15.626uA step size and the range from 0 to 1000uA. | F8: 13 | G8: 8 | H8: 6 | I8: RW
A9: 4160 | B9: =_xlfn.CONCAT("0x",DEC2HEX(A9,4)) -> 0x1040 | C9: ="bias_ctrl" & "_" & (A9-4152) -> bias_ctrl_8 | D9: d2a_CH0_V_PTAT_St1 | E9: PTAT current bias of PA for CH0 V | F9: 5 | G9: 0 | H9: 6 | I9: RW
A10: 4160 | B10: =_xlfn.CONCAT("0x",DEC2HEX(A10,4)) -> 0x1040 | C10: ="bias_ctrl" & "_" & (A10-4152) -> bias_ctrl_8 | D10: d2a_CH0_V_PTAT_St2 | E10: PTAT current bias of PA Driver for CH0 V | F10: 13 | G10: 8 | H10: 6 | I10: RW
A11: 4164 | B11: =_xlfn.CONCAT("0x",DEC2HEX(A11,4)) -> 0x1044 | C11: ="bias_ctrl" & "_" & (A11-4152) -> bias_ctrl_12 | D11: d2a_CH0_V_PTAT_St3 | E11: PTAT current bias of combiner for CH0 V | F11: 5 | G11: 0 | H11: 6 | I11: RW
A12: 4164 | B12: =_xlfn.CONCAT("0x",DEC2HEX(A12,4)) -> 0x1044 | C12: ="bias_ctrl" & "_" & (A12-4152) -> bias_ctrl_12 | D12: d2a_CH0_V_CTAT | E12: <3:1> to efuse; CTAT current for 3to1 Comb with 15.626uA step size and the range from 0 to 1000uA. | F12: 13 | G12: 8 | H12: 6 | I12: RW
A13: 4153 | B13: =_xlfn.CONCAT("0x",DEC2HEX(A13,4)) -> 0x1039 | C13: ="bias_ctrl" & "_" & (A13-4152) -> bias_ctrl_1 | D13: d2a_CH1_H_PTAT_St1 | E13: PTAT current bias of PA for CH1 H | F13: 5 | G13: 0 | H13: 6 | I13: RW
A14: 4153 | B14: =_xlfn.CONCAT("0x",DEC2HEX(A14,4)) -> 0x1039 | C14: ="bias_ctrl" & "_" & (A14-4152) -> bias_ctrl_1 | D14: d2a_CH1_H_PTAT_St2 | E14: PTAT current bias of PA Driver for CH1 H | F14: 13 | G14: 8 | H14: 6 | I14: RW
A15: 4157 | B15: =_xlfn.CONCAT("0x",DEC2HEX(A15,4)) -> 0x103D | C15: ="bias_ctrl" & "_" & (A15-4152) -> bias_ctrl_5 | D15: d2a_CH1_H_PTAT_St3 | E15: PTAT current bias of combiner for CH1 H | F15: 5 | G15: 0 | H15: 6 | I15: RW
A16: 4157 | B16: =_xlfn.CONCAT("0x",DEC2HEX(A16,4)) -> 0x103D | C16: ="bias_ctrl" & "_" & (A16-4152) -> bias_ctrl_5 | D16: d2a_CH1_H_CTAT | E16: <3:1> to efuse; CTAT current for 3to1 Comb with 15.626uA step size and the range from 0 to 1000uA. | F16: 13 | G16: 8 | H16: 6 | I16: RW
... A39: 4172 | B39: =_xlfn.CONCAT("0x",DEC2HEX(A39,4)) -> 0x104C | C39: ="bias_ctrl" & "_" & (A39-4152) -> bias_ctrl_20 | D39: d2a_DIST_B0_St2_0_PTAT | E39: PTAT current bias for the CH0-1 St2 distribution network at Beam 0 | F39: 13 | G39: 8 | H39: 6 | I39: RW
A40: 4173 | B40: =_xlfn.CONCAT("0x",DEC2HEX(A40,4)) -> 0x104D | C40: ="bias_ctrl" & "_" & (A40-4152) -> bias_ctrl_21 | D40: d2a_DIST_B0_St2_1_PTAT | E40: PTAT current bias for the CH2-3 St2 distribution network at Beam 0 | F40: 5 | G40: 0 | I40: RW
A41: 4174 | B41: =_xlfn.CONCAT("0x",DEC2HEX(A41,4)) -> 0x104E | C41: ="bias_ctrl" & "_" & (A41-4152) -> bias_ctrl_22 | D41: d2a_DIST_B1_St1_PTAT | E41: PTAT current bias for the St1 distribution network at Beam 1 | F41: 5 | G41: 0 | H41: 6 | I41: RW
A42: 4174 | B42: =_xlfn.CONCAT("0x",DEC2HEX(A42,4)) -> 0x104E | C42: ="bias_ctrl" & "_" & (A42-4152) -> bias_ctrl_22 | D42: d2a_DIST_B1_St2_0_PTAT | E42: PTAT current bias for the CH0-1 St2 distribution network at Beam 1 | F42: 13 | G42: 8 | H42: 6 | I42: RW
A43: 4175 | B43: =_xlfn.CONCAT("0x",DEC2HEX(A43,4)) -> 0x104F | C43: ="bias_ctrl" & "_" & (A43-4152) -> bias_ctrl_23 | D43: d2a_DIST_B1_St2_1_PTAT | E43: PTAT current bias for the CH2-3 St2 distribution network at Beam 1 | F43: 5 | G43: 0 | H43: 6 | I43: RW
A44: 4173 | B44: =_xlfn.CONCAT("0x",DEC2HEX(A44,4)) -> 0x104D | C44: ="bias_ctrl" & "_" & (A44-4152) -> bias_ctrl_21 | D44: d2a_DIST_B0_St1_cbias | E44: <2:0> for DIST St1 middle cascode device gate bias at Beam 0 | F44: 8 | G44: 6 | H44: 3 | I44: RW
A45: 4173 | B45: =_xlfn.CONCAT("0x",DEC2HEX(A45,4)) -> 0x104D | C45: ="bias_ctrl" & "_" & (A45-4152) -> bias_ctrl_21 | D45: d2a_DIST_B0_St2_0_cbias | E45: <2:0> for DIST St2_0 and St2_1 middle cascode device gate bias at Beam 0 | F45: 11 | G45: 9 | H45: 3 | I45: RW
A46: 4173 | B46: =_xlfn.CONCAT("0x",DEC2HEX(A46,4)) -> 0x104D | C46: ="bias_ctrl" & "_" & (A46-4152) -> bias_ctrl_21 | D46: d2a_DIST_B0_St2_1_cbias | E46: <2:0> for DIST St2_0 and St2_1 bottom gm device gate bias at Beam 0 | F46: 14 | G46: 12 | H46: 3 | I46: RW
A47: 4175 | B47: =_xlfn.CONCAT("0x",DEC2HEX(A47,4)) -> 0x104F | C47: ="bias_ctrl" & "_" & (A47-4152) -> bias_ctrl_23 | D47: d2a_DIST_B1_St1_cbias | E47: <2:0> for DIST St1 middle cascode device gate bias at Beam 1 | F47: 8 | G47: 6 | H47: 3 | I47: RW
A48: 4175 | B48: =_xlfn.CONCAT("0x",DEC2HEX(A48,4)) -> 0x104F | C48: ="bias_ctrl" & "_" & (A48-4152) -> bias_ctrl_23 | D48: d2a_DIST_B1_St2_0_cbias | E48: <2:0> for DIST St2_0 and St2_1 middle cascode device gate bias at Beam 1 | F48: 11 | G48: 9 | H48: 3 | I48: RW
A49: 4175 | B49: =_xlfn.CONCAT("0x",DEC2HEX(A49,4)) -> 0x104F | C49: ="bias_ctrl" & "_" & (A49-4152) -> bias_ctrl_23 | D49: d2a_DIST_B1_St2_1_cbias | E49: <2:0> for DIST St2_0 and St2_1 bottom gm device gate bias at Beam 1 | F49: 14 | G49: 12 | H49: 3 | I49: RW
A50: 4180 | B50: =_xlfn.CONCAT("0x",DEC2HEX(A50,4)) -> 0x1054 | C50: ="bias_ctrl" & "_" & (A50-4152) -> bias_ctrl_28 | D50: d2a_daisy_chain0_bias | E50: Unused used for extra fuse values | F50: 5 | G50: 0 | H50: 6 | I50: R
A51: 4180 | B51: =_xlfn.CONCAT("0x",DEC2HEX(A51,4)) -> 0x1054 | C51: ="bias_ctrl" & "_" & (A51-4152) -> bias_ctrl_28 | D51: d2a_daisy_chain1_bias | E51: Unused used for extra fuse values | F51: 13 | G51: 8 | H51: 6 | I51: R
A52: 4181 | B52: =_xlfn.CONCAT("0x",DEC2HEX(A52,4)) -> 0x1055 | C52: ="bias_ctrl" & "_" & (A52-4152) -> bias_ctrl_29 | D52: d2a_daisy_chain2_bias | E52: Unused used for extra fuse values | F52: 5 | G52: 0 | H52: 6 | I52: R
... A56: 4185 | B56: =_xlfn.CONCAT("0x",DEC2HEX(A56,4)) -> 0x1059 | C56: ="bias_ctrl" & "_" & (A56-4152) -> bias_ctrl_33 | D56: d2a_extra_bits_2 | E56: <4:0> for d2a_bias_adjust<4:0> <7:6> reserved bits <5> for d2a_slope_2x_en | F56: 7 | G56: 0 | H56: 8 | I56: RW

Sheet ADC
A1: Address Offset | C1: Revision date | D1: Revision | E1: ED
A2: N/A | C2: =Setup!B2 -> 46161 | D2: =Setup!C2 -> PA3 | E2: Stampede
A3: Address | B3: Address hex | C3: Reg Name | D3: Field Name | E3: Description | F3: Msb | G3: Lsb | H3: Bit Length | I3: Type | J3: Default | K3: Signal Name | L3: Dir
A5: 4124 | B5: =_xlfn.CONCAT("0x",DEC2HEX(A5,4)) -> 0x101C | C5: ch0_pd_dctest_ctrl | D5: ch0_v_pd_en | E5: Channel 0 V power detector ADC enable | F5: 0 | G5: 0 | H5: 1 | I5: RW
A6: 4124 | B6: =_xlfn.CONCAT("0x",DEC2HEX(A6,4)) -> 0x101C | C6: ch0_pd_dctest_ctrl | D6: ch0_v_pd_enbgr | E6: Channel 0 V power detector LDO BGR enable | F6: 1 | G6: 1 | H6: 1 | I6: RW
A7: 4124 | B7: =_xlfn.CONCAT("0x",DEC2HEX(A7,4)) -> 0x101C | C7: ch0_pd_dctest_ctrl | D7: ch0_h_pd_en | E7: Channel 0 H power detector ADC enable | F7: 2 | G7: 2 | H7: 1 | I7: RW
A8: 4124 | B8: =_xlfn.CONCAT("0x",DEC2HEX(A8,4)) -> 0x101C | C8: ch0_pd_dctest_ctrl | D8: ch0_h_pd_enbgr | E8: Channel 0 H power detector LDO BGR enable | F8: 3 | G8: 3 | H8: 1 | I8: RW
A9: 4124 | B9: =_xlfn.CONCAT("0x",DEC2HEX(A9,4)) -> 0x101C | C9: ch0_pd_dctest_ctrl | D9: ch0_dctest_en | E9: DC test enable for CH0: <0> CH0_V PA/DRV, <1> CH0_V comb, <2> CH0_H PA/DRV, <3> CH0_H comb | F9: 7 | G9: 4 | H9: 4 | I9: RW
A10: 4125 | B10: =_xlfn.CONCAT("0x",DEC2HEX(A10,4)) -> 0x101D | C10: ch1_pd_dctest_ctrl | D10: ch1_v_pd_en | E10: Channel 1 V power detector ADC enable | F10: 0 | G10: 0 | H10: 1 | I10: RW
A11: 4125 | B11: =_xlfn.CONCAT("0x",DEC2HEX(A11,4)) -> 0x101D | C11: ch1_pd_dctest_ctrl | D11: ch1_v_pd_enbgr | E11: Channel 1 V power detector LDO BGR enable | F11: 1 | G11: 1 | H11: 1 | I11: RW
A12: 4125 | B12: =_xlfn.CONCAT("0x",DEC2HEX(A12,4)) -> 0x101D | C12: ch1_pd_dctest_ctrl | D12: ch1_h_pd_en | E12: Channel 1 H power detector ADC enable | F12: 2 | G12: 2 | H12: 1 | I12: RW
A13: 4125 | B13: =_xlfn.CONCAT("0x",DEC2HEX(A13,4)) -> 0x101D | C13: ch1_pd_dctest_ctrl | D13: ch1_h_pd_enbgr | E13: Channel 1 H power detector LDO BGR enable | F13: 3 | G13: 3 | H13: 1 | I13: RW
A14: 4125 | B14: =_xlfn.CONCAT("0x",DEC2HEX(A14,4)) -> 0x101D | C14: ch1_pd_dctest_ctrl | D14: ch1_dctest_en | E14: DC test enable for CH1: <0> CH1_V PA/DRV, <1> CH1_V comb, <2> CH1_H PA/DRV, <3> CH1_H comb | F14: 7 | G14: 4 | H14: 4 | I14: RW
A15: 4126 | B15: =_xlfn.CONCAT("0x",DEC2HEX(A15,4)) -> 0x101E | C15: ch2_pd_dctest_ctrl | D15: ch2_v_pd_en | E15: Channel 2 V power detector ADC enable | F15: 0 | G15: 0 | H15: 1 | I15: RW
A16: 4126 | B16: =_xlfn.CONCAT("0x",DEC2HEX(A16,4)) -> 0x101E | C16: ch2_pd_dctest_ctrl | D16: ch2_v_pd_enbgr | E16: Channel 2 V power detector LDO BGR enable | F16: 1 | G16: 1 | H16: 1 | I16: RW
... A64: 4151 | B64: =_xlfn.CONCAT("0x",DEC2HEX(A64,4)) -> 0x1037 | C64: ch3_pd_gc | D64: ch3_v_pd_gc | E64: Channel 3 V power detector gain control [1:0] | F64: 3 | G64: 2 | H64: 2 | I64: RW

Sheet MACRO
A1: Address Offset | C1: Revision date | D1: Revision | E1: ED
A2: N/A | C2: =Setup!B2 -> 46161 | D2: =Setup!C2 -> PA3 | E2: Stampede
A3: Address | B3: Address hex | C3: Reg Name | D3: Field Name | E3: Description | F3: Msb | G3: Lsb | H3: Bit Length | I3: Type | J3: Default | K3: Signal Name | L3: Dir | M3: Macro MSB | N3: Macro LSB
A5: 4104 | B5: =_xlfn.CONCAT("0x",DEC2HEX(A5,4)) -> 0x1008 | C5: center_control | D5: d2a_center_bias_en | E5: Bias gen and BG | F5: 1 | G5: 0 | H5: 2 | I5: RW | M5: 1 | N5: 0
A6: 4105 | B6: =_xlfn.CONCAT("0x",DEC2HEX(A6,4)) -> 0x1009 | C6: center_dist_b0 | D6: d2a_center_bias_en | E6: DIST Bias generation bit B0 | F6: 8 | G6: 8 | H6: 1 | I6: RW | M6: 2 | N6: 2
A7: 4106 | B7: =_xlfn.CONCAT("0x",DEC2HEX(A7,4)) -> 0x100A | C7: center_dist_b1 | D7: d2a_center_bias_en | E7: DIST Bias generation bit B1 | F7: 8 | G7: 8 | H7: 1 | I7: RW | M7: 3 | N7: 3
A8: 4107 | B8: =_xlfn.CONCAT("0x",DEC2HEX(A8,4)) -> 0x100B | C8: temp_adc_dctest_pwrdn | D8: d2a_center_bias_en | E8: 1.8-V ANA power-gated SW for DCTEST ADC and Temp Sensor | F8: 8 | G8: 8 | H8: 1 | I8: RW | M8: 4 | N8: 4

Sheet EFUSE_INSTRUCTIONS
A1: Address Offset | C1: Revision date | D1: Revision | E1: ED | L1: Type definitions: R = read, W = Write, RCLR = Read and clear, CLR = Clear (set to 0), CLR-REG = -REG extension makes the application to full register instead of just field
A2: N/A | C2: =[1]Setup!B2 -> 46161 | D2: =[1]Setup!C2 -> PA1 | E2: Blueway | M2: Value ID is like a variable. Say <row1> Type = R, ID = gb, then another row <row2> Type = W, ID = gb. This mean read field in row 1 and write to row 2. if ID == FIXED then write what is in column Fixed Value
A3: Address | B3: Address hex | C3: Reg Name | D3: Field Name | E3: Description | F3: Msb | G3: Lsb | H3: Bit Length | I3: Revision Name | J3: Revision Value | K3: Instruction ID | L3: Type | M3: Value ID | N3: Fixed Value
A5: 4181 | B5: =_xlfn.CONCAT("0x",DEC2HEX(A5,4)) -> 0x1055 | C5: ="bias_ctrl" & "_" & (A5-4152) -> bias_ctrl_29 | D5: d2a_daisy_chain3_bias | E5: Unused used for extra fuse values | F5: 13 | G5: 8 | H5: 6 | I5: rev_1 | J5: 0 | K5: 0 | L5: RCLR | M5: global_bias
A6: 4185 | B6: =_xlfn.CONCAT("0x",DEC2HEX(A6,4)) -> 0x1059 | C6: ="bias_ctrl" & "_" & (A6-4152) -> bias_ctrl_33 | D6: d2a_extra_bits_2 | E6: <4:0> for d2a_bias_adjust<4:0> <7:6> reserved bits <5> for d2a_slope_2x_en | F6: 7 | G6: 0 | H6: 8 | I6: rev_1 | J6: 0 | K6: 1 | L6: W | M6: global_bias
A7: 4184 | B7: =_xlfn.CONCAT("0x",DEC2HEX(A7,4)) -> 0x1058 | C7: ="bias_ctrl" & "_" & (A7-4152) -> bias_ctrl_32 | D7: d2a_extra_bits_0 | E7: <7:6> for the DSIT St1 B0 input captune <5:3> for top cascode gate bias <2:0> for DIST St1 bottom gm device gate bias | F7: 7 | G7: 0 | H7: 8 | I7: rev_1 | J7: 0 | K7: 2 | L7: R | M7: cap
A8: 4184 | B8: =_xlfn.CONCAT("0x",DEC2HEX(A8,4)) -> 0x1058 | C8: ="bias_ctrl" & "_" & (A8-4152) -> bias_ctrl_32 | D8: d2a_extra_bits_1 | E8: <7:6> for the DSIT St1 B1 input captune <5:3> for top cascode gate bias <2:0> for DIST St1 bottom gm device gate bias | F8: 15 | G8: 8 | H8: 8 | I8: rev_1 | J8: 0 | K8: 3 | L8: W | M8: cap
A9: 4200 | B9: =_xlfn.CONCAT("0x",DEC2HEX(A9,4)) -> 0x1068 | C9: ch0_captune | D9: ch0_h_comb_in_captune | E9: Capacitance tune for CH0 H combiner input [2:0] | F9: 2 | G9: 0 | H9: 3 | I9: rev_1 | J9: 0 | K9: 4 | L9: CLR-REG | N9: 0
A10: 4201 | B10: =_xlfn.CONCAT("0x",DEC2HEX(A10,4)) -> 0x1069 | C10: ch1_captune | D10: ch1_h_comb_in_captune | E10: Capacitance tune for CH1 H combiner input [2:0] | F10: 2 | G10: 0 | H10: 3 | I10: rev_1 | J10: 0 | K10: 5 | L10: CLR-REG | N10: 0
A11: 4202 | B11: =_xlfn.CONCAT("0x",DEC2HEX(A11,4)) -> 0x106A | C11: ch2_captune | D11: ch2_h_comb_in_captune | E11: Capacitance tune for CH2 H combiner input [2:0] | F11: 2 | G11: 0 | H11: 3 | I11: rev_1 | J11: 0 | K11: 6 | L11: CLR-REG | N11: 0
A12: 4203 | B12: =_xlfn.CONCAT("0x",DEC2HEX(A12,4)) -> 0x106B | C12: ch3_captune | D12: ch3_h_comb_in_captune | E12: Capacitance tune for CH3 H combiner input [2:0] | F12: 2 | G12: 0 | H12: 3 | I12: rev_1 | J12: 0 | K12: 7 | L12: CLR-REG | N12: 0
